Workbook

Sheet IO_sub_model
E3: A | F3: A | G3: A | H3: B | I3: B | J3: B | K3: C | L3: C | M3: C
D4: Z | E4: Agr | F4: Ind | G4: Serv | H4: Agr | I4: Ind | J4: Serv | K4: Agr | L4: Ind | M4: Serv | N4: FD | O4: X | P4: AX | Q4: X
C5: A | D5: Agr | E5: 10 | F5: 5 | G5: 10 | H5: 1 | I5: 0 | J5: 8 | K5: 3 | L5: 7 | M5: 2 | N5: 25 | O5: =+SUM(E5:N5) -> 71 | P5: {=+MMULT(E21:M29,O5:O13)} -> 46 | Q5: =+P5+N5 -> 71 | R5: =+Q5=O5 -> TRUE
C6: A | D6: Ind | E6: 8 | F6: 3 | G6: 9 | H6: 4 | I6: 2 | J6: 10 | K6: 1 | L6: 4 | M6: 7 | N6: 7 | O6: =+SUM(E6:N6) -> 55 | P6: 48 | Q6: =+P6+N6 -> 55 | R6: =+Q6=O6 -> TRUE
C7: A | D7: Serv | E7: 0 | F7: 0 | G7: 0 | H7: 7 | I7: 4 | J7: 4 | K7: 7 | L7: 4 | M7: 7 | N7: 14 | O7: =+SUM(E7:N7) -> 47 | P7: 33 | Q7: =+P7+N7 -> 47 | R7: =+Q7=O7 -> TRUE
C8: B | D8: =+D5 -> Agr | E8: 9 | F8: 5 | G8: 4 | H8: 7 | I8: 10 | J8: 9 | K8: 10 | L8: 9 | M8: 9 | N8: 10 | O8: =+SUM(E8:N8) -> 82 | P8: 72 | Q8: =+P8+N8 -> 82 | R8: =+Q8=O8 -> TRUE
C9: B | D9: =+D6 -> Ind | E9: 4 | F9: 2 | G9: 3 | H9: 6 | I9: 7 | J9: 4 | K9: 9 | L9: 2 | M9: 8 | N9: 5 | O9: =+SUM(E9:N9) -> 50 | P9: 45 | Q9: =+P9+N9 -> 50 | R9: =+Q9=O9 -> TRUE
C10: B | D10: =+D7 -> Serv | E10: 6 | F10: 5 | G10: 4 | H10: 1 | I10: 9 | J10: 2 | K10: 1 | L10: 6 | M10: 1 | N10: 20 | O10: =+SUM(E10:N10) -> 55 | P10: 35 | Q10: =+P10+N10 -> 55 | R10: =+Q10=O10 -> TRUE
C11: C | D11: =+D8 -> Agr | E11: 3 | F11: 10 | G11: 8 | H11: 9 | I11: 10 | J11: 0 | K11: 7 | L11: 9 | M11: 8 | N11: 15 | O11: =+SUM(E11:N11) -> 79 | P11: 64 | Q11: =+P11+N11 -> 79 | R11: =+Q11=O11 -> TRUE
C12: C | D12: =+D9 -> Ind | E12: 1 | F12: 8 | G12: 0 | H12: 9 | I12: 0 | J12: 0 | K12: 8 | L12: 10 | M12: 1 | N12: 28 | O12: =+SUM(E12:N12) -> 65 | P12: 37 | Q12: =+P12+N12 -> 65 | R12: =+Q12=O12 -> TRUE
C13: C | D13: =+D10 -> Serv | E13: 10 | F13: 2 | G13: 4 | H13: 10 | I13: 0 | J13: 0 | K13: 3 | L13: 0 | M13: 7 | N13: 24 | O13: =+SUM(E13:N13) -> 60 | P13: 36 | Q13: =+P13+N13 -> 60 | R13: =+Q13=O13 -> TRUE
D14: VA | E14: 20 | F14: 15 | G14: 5 | H14: 28 | I14: 8 | J14: 18 | K14: 30 | L14: 14 | M14: 10 | N14: =+SUM(E5:M13) -> 416 | O14: =SUM(O5:O13) -> 564
D15: X | E15: =SUM(E5:E14) -> 71 | F15: =SUM(F5:F14) -> 55 | G15: =SUM(G5:G14) -> 47 | H15: =SUM(H5:H14) -> 82 | I15: =SUM(I5:I14) -> 50 | J15: =SUM(J5:J14) -> 55 | K15: =SUM(K5:K14) -> 79 | L15: =SUM(L5:L14) -> 65 | M15: =SUM(M5:M14) -> 60
E16: {=+TRANSPOSE(O5:O13)} -> 71 | F16: 55 | G16: 47 | H16: 82 | I16: 50 | J16: 55 | K16: 79 | L16: 65 | M16: 60
E17: =+E15-E16 -> 0 | F17: =+F15-F16 -> 0 | G17: =+G15-G16 -> 0 | H17: =+H15-H16 -> 0 | I17: =+I15-I16 -> 0 | J17: =+J15-J16 -> 0 | K17: =+K15-K16 -> 0 | L17: =+L15-L16 -> 0 | M17: =+M15-M16 -> 0
E19: A | F19: A | G19: A | H19: B | I19: B | J19: B | K19: C | L19: C | M19: C
D20: A | E20: Agr | F20: Ind | G20: Serv | H20: Agr | I20: Ind | J20: Serv | K20: Agr | L20: Ind | M20: Serv
C21: A | D21: Agr | E21: =+E5/E$15 -> 0.14084507 | F21: =+F5/F$15 -> 0.090909091 | G21: =+G5/G$15 -> 0.21276596 | H21: =+H5/H$15 -> 0.012195122 | I21: =+I5/I$15 -> 0 | J21: =+J5/J$15 -> 0.14545455 | K21: =+K5/K$15 -> 0.037974684 | L21: =+L5/L$15 -> 0.10769231 | M21: =+M5/M$15 -> 0.033333333
C22: A | D22: Ind | E22: =+E6/E$15 -> 0.11267606 | F22: =+F6/F$15 -> 0.054545455 | G22: =+G6/G$15 -> 0.19148936 | H22: =+H6/H$15 -> 0.048780488 | I22: =+I6/I$15 -> 0.04 | J22: =+J6/J$15 -> 0.18181818 | K22: =+K6/K$15 -> 0.012658228 | L22: =+L6/L$15 -> 0.061538462 | M22: =+M6/M$15 -> 0.11666667
C23: A | D23: Serv | E23: =+E7/E$15 -> 0 | F23: =+F7/F$15 -> 0 | G23: =+G7/G$15 -> 0 | H23: =+H7/H$15 -> 0.085365854 | I23: =+I7/I$15 -> 0.08 | J23: =+J7/J$15 -> 0.072727273 | K23: =+K7/K$15 -> 0.088607595 | L23: =+L7/L$15 -> 0.061538462 | M23: =+M7/M$15 -> 0.11666667
C24: B | D24: =+D21 -> Agr | E24: =+E8/E$15 -> 0.12676056 | F24: =+F8/F$15 -> 0.090909091 | G24: =+G8/G$15 -> 0.085106383 | H24: =+H8/H$15 -> 0.085365854 | I24: =+I8/I$15 -> 0.2 | J24: =+J8/J$15 -> 0.16363636 | K24: =+K8/K$15 -> 0.12658228 | L24: =+L8/L$15 -> 0.13846154 | M24: =+M8/M$15 -> 0.15
C25: B | D25: =+D22 -> Ind | E25: =+E9/E$15 -> 0.056338028 | F25: =+F9/F$15 -> 0.036363636 | G25: =+G9/G$15 -> 0.063829787 | H25: =+H9/H$15 -> 0.073170732 | I25: =+I9/I$15 -> 0.14 | J25: =+J9/J$15 -> 0.072727273 | K25: =+K9/K$15 -> 0.11392405 | L25: =+L9/L$15 -> 0.030769231 | M25: =+M9/M$15 -> 0.13333333
C26: B | D26: =+D23 -> Serv | E26: =+E10/E$15 -> 0.084507042 | F26: =+F10/F$15 -> 0.090909091 | G26: =+G10/G$15 -> 0.085106383 | H26: =+H10/H$15 -> 0.012195122 | I26: =+I10/I$15 -> 0.18 | J26: =+J10/J$15 -> 0.036363636 | K26: =+K10/K$15 -> 0.012658228 | L26: =+L10/L$15 -> 0.092307692 | M26: =+M10/M$15 -> 0.016666667
C27: C | D27: =+D24 -> Agr | E27: =+E11/E$15 -> 0.042253521 | F27: =+F11/F$15 -> 0.18181818 | G27: =+G11/G$15 -> 0.17021277 | H27: =+H11/H$15 -> 0.1097561 | I27: =+I11/I$15 -> 0.2 | J27: =+J11/J$15 -> 0 | K27: =+K11/K$15 -> 0.088607595 | L27: =+L11/L$15 -> 0.13846154 | M27: =+M11/M$15 -> 0.13333333
C28: C | D28: =+D25 -> Ind | E28: =+E12/E$15 -> 0.014084507 | F28: =+F12/F$15 -> 0.14545455 | G28: =+G12/G$15 -> 0 | H28: =+H12/H$15 -> 0.1097561 | I28: =+I12/I$15 -> 0 | J28: =+J12/J$15 -> 0 | K28: =+K12/K$15 -> 0.10126582 | L28: =+L12/L$15 -> 0.15384615 | M28: =+M12/M$15 -> 0.016666667
C29: C | D29: =+D26 -> Serv | E29: =+E13/E$15 -> 0.14084507 | F29: =+F13/F$15 -> 0.036363636 | G29: =+G13/G$15 -> 0.085106383 | H29: =+H13/H$15 -> 0.12195122 | I29: =+I13/I$15 -> 0 | J29: =+J13/J$15 -> 0 | K29: =+K13/K$15 -> 0.037974684 | L29: =+L13/L$15 -> 0 | M29: =+M13/M$15 -> 0.11666667
D30: VA | E30: =+E14/E$15 -> 0.28169014 | F30: =+F14/F$15 -> 0.27272727 | G30: =+G14/G$15 -> 0.10638298 | H30: =+H14/H$15 -> 0.34146341 | I30: =+I14/I$15 -> 0.16 | J30: =+J14/J$15 -> 0.32727273 | K30: =+K14/K$15 -> 0.37974684 | L30: =+L14/L$15 -> 0.21538462 | M30: =+M14/M$15 -> 0.16666667
D31: X | E31: =SUM(E21:E30) -> 1 | F31: =SUM(F21:F30) -> 1 | G31: =SUM(G21:G30) -> 1 | H31: =SUM(H21:H30) -> 1 | I31: =SUM(I21:I30) -> 1 | J31: =SUM(J21:J30) -> 1 | K31: =SUM(K21:K30) -> 1 | L31: =SUM(L21:L30) -> 1 | M31: =SUM(M21:M30) -> 1
E34: A | F34: A | G34: A | H34: B | I34: B | J34: B | K34: C | L34: C | M34: C
D35: L | E35: Agr | F35: Ind | G35: Serv | H35: Agr | I35: Ind | J35: Serv | K35: Agr | L35: Ind | M35: Serv
C36: A | D36: Agr | E36: {=+MINVERSE(_xlfn.MUNIT(COUNTA($D$36:$D$44))-E21:M29)} -> 1.3396898 | F36: 0.29313766 | G36: 0.46062081 | H36: 0.20047115 | I36: 0.22471967 | J36: 0.3432924 | K36: 0.21398444 | L36: 0.33876648 | M36: 0.26323813 | N36: {=+MMULT(_xlfn.ANCHORARRAY(E36),N5:N13)} -> 71
C37: A | D37: Ind | E37: 0.33305376 | F37: 1.2588963 | G37: 0.44906572 | H37: 0.24914152 | I37: 0.28508256 | J37: 0.38551433 | K37: 0.19834507 | L37: 0.2922519 | M37: 0.36621325 | N37: 55
C38: A | D38: Serv | E38: 0.16096426 | F38: 0.16098913 | G38: 1.1866305 | H38: 0.2426696 | I38: 0.27162889 | J38: 0.20593716 | K38: 0.23314113 | L38: 0.22869829 | M38: 0.30966204 | N38: 47
C39: B | D39: =+D36 -> Agr | E39: 0.4694894 | F39: 0.42979984 | G39: 0.50026322 | H39: 1.4082652 | I39: 0.59296552 | J39: 0.47360784 | K39: 0.42917418 | L39: 0.50129475 | M39: 0.55237411 | N39: 82
C40: B | D40: =+D37 -> Ind | E40: 0.27827723 | F40: 0.24820394 | G40: 0.33029476 | H40: 0.284956 | I40: 1.3995953 | J40: 0.26778154 | K40: 0.31054186 | L40: 0.25504175 | M40: 0.40329378 | N40: 50
C41: B | D41: =+D38 -> Serv | E41: 0.24935171 | F41: 0.25257975 | G41: 0.28900631 | H41: 0.17116188 | I41: 0.36899675 | J41: 1.2017562 | K41: 0.16782505 | L41: 0.27111308 | M41: 0.21882465 | N41: 55
C42: C | D42: =+D39 -> Agr | E42: 0.35214837 | F42: 0.4808315 | G42: 0.54248305 | H42: 0.42036737 | I42: 0.55309703 | J42: 0.29794582 | K42: 1.3766391 | L42: 0.46591317 | M42: 0.52551987 | N42: 79
C43: C | D43: =+D40 -> Ind | E43: 0.1889523 | F43: 0.33840247 | G43: 0.22055756 | H43: 0.28461936 | I43: 0.19938771 | J43: 0.1723962 | K43: 0.26168767 | L43: 1.3619713 | M43: 0.22783339 | N43: 65
C44: C | D44: =+D41 -> Serv | E44: 0.32278456 | F44: 0.19408334 | G44: 0.29864604 | H44: 0.27809522 | I44: 0.17937872 | J44: 0.16864275 | K44: 0.18317972 | L44: 0.17731814 | M44: 1.3178106 | N44: 60
C46: Demand shock | E46: d_shock | F46: 1-d_shock | G46: FD | H46: fd_max | J46: Supply shock | L46: p_shock | M46: 1-p_shock | N46: X | O46: x_max
...

Sheet IO_sub_model - t+1
E3: A | F3: A | G3: A | H3: B | I3: B | J3: B | K3: C | L3: C | M3: C
D4: Z | E4: Agr | F4: Ind | G4: Serv | H4: Agr | I4: Ind | J4: Serv | K4: Agr | L4: Ind | M4: Serv | N4: FD | O4: X | P4: AX | Q4: X
C5: A | D5: Agr | E5: 10 | F5: 5 | G5: 10 | H5: 1 | I5: 0 | J5: 8 | K5: 3 | L5: 7 | M5: 2 | N5: 25 | O5: =+SUM(E5:N5) -> 71 | P5: {=+MMULT(E21:M29,O5:O13)} -> 46 | Q5: =+P5+N5 -> 71 | R5: =+Q5=O5 -> TRUE
C6: A | D6: Ind | E6: 8 | F6: 3 | G6: 9 | H6: 4 | I6: 2 | J6: 10 | K6: 1 | L6: 4 | M6: 7 | N6: 7 | O6: =+SUM(E6:N6) -> 55 | P6: 48 | Q6: =+P6+N6 -> 55 | R6: =+Q6=O6 -> TRUE
C7: A | D7: Serv | E7: 0 | F7: 0 | G7: 0 | H7: 7 | I7: 4 | J7: 4 | K7: 7 | L7: 4 | M7: 7 | N7: 14 | O7: =+SUM(E7:N7) -> 47 | P7: 33 | Q7: =+P7+N7 -> 47 | R7: =+Q7=O7 -> TRUE
C8: B | D8: =+D5 -> Agr | E8: 9 | F8: 5 | G8: 4 | H8: 7 | I8: 10 | J8: 9 | K8: 10 | L8: 9 | M8: 9 | N8: 10 | O8: =+SUM(E8:N8) -> 82 | P8: 72 | Q8: =+P8+N8 -> 82 | R8: =+Q8=O8 -> TRUE
C9: B | D9: =+D6 -> Ind | E9: 4 | F9: 2 | G9: 3 | H9: 6 | I9: 7 | J9: 4 | K9: 9 | L9: 2 | M9: 8 | N9: 5 | O9: =+SUM(E9:N9) -> 50 | P9: 45 | Q9: =+P9+N9 -> 50 | R9: =+Q9=O9 -> TRUE
C10: B | D10: =+D7 -> Serv | E10: 6 | F10: 5 | G10: 4 | H10: 1 | I10: 9 | J10: 2 | K10: 1 | L10: 6 | M10: 1 | N10: 20 | O10: =+SUM(E10:N10) -> 55 | P10: 35 | Q10: =+P10+N10 -> 55 | R10: =+Q10=O10 -> TRUE
C11: C | D11: =+D8 -> Agr | E11: 3 | F11: 10 | G11: 8 | H11: 9 | I11: 10 | J11: 0 | K11: 7 | L11: 9 | M11: 8 | N11: 15 | O11: =+SUM(E11:N11) -> 79 | P11: 64 | Q11: =+P11+N11 -> 79 | R11: =+Q11=O11 -> TRUE
C12: C | D12: =+D9 -> Ind | E12: 1 | F12: 8 | G12: 0 | H12: 9 | I12: 0 | J12: 0 | K12: 8 | L12: 10 | M12: 1 | N12: 28 | O12: =+SUM(E12:N12) -> 65 | P12: 37 | Q12: =+P12+N12 -> 65 | R12: =+Q12=O12 -> TRUE
C13: C | D13: =+D10 -> Serv | E13: 10 | F13: 2 | G13: 4 | H13: 10 | I13: 0 | J13: 0 | K13: 3 | L13: 0 | M13: 7 | N13: 24 | O13: =+SUM(E13:N13) -> 60 | P13: 36 | Q13: =+P13+N13 -> 60 | R13: =+Q13=O13 -> TRUE
D14: VA | E14: 20 | F14: 15 | G14: 5 | H14: 28 | I14: 8 | J14: 18 | K14: 30 | L14: 14 | M14: 10 | N14: =+SUM(E5:M13) -> 416 | O14: =SUM(O5:O13) -> 564
D15: X | E15: =SUM(E5:E14) -> 71 | F15: =SUM(F5:F14) -> 55 | G15: =SUM(G5:G14) -> 47 | H15: =SUM(H5:H14) -> 82 | I15: =SUM(I5:I14) -> 50 | J15: =SUM(J5:J14) -> 55 | K15: =SUM(K5:K14) -> 79 | L15: =SUM(L5:L14) -> 65 | M15: =SUM(M5:M14) -> 60
E16: {=+TRANSPOSE(O5:O13)} -> 71 | F16: 55 | G16: 47 | H16: 82 | I16: 50 | J16: 55 | K16: 79 | L16: 65 | M16: 60
E17: =+E15-E16 -> 0 | F17: =+F15-F16 -> 0 | G17: =+G15-G16 -> 0 | H17: =+H15-H16 -> 0 | I17: =+I15-I16 -> 0 | J17: =+J15-J16 -> 0 | K17: =+K15-K16 -> 0 | L17: =+L15-L16 -> 0 | M17: =+M15-M16 -> 0
E19: A | F19: A | G19: A | H19: B | I19: B | J19: B | K19: C | L19: C | M19: C
D20: A | E20: Agr | F20: Ind | G20: Serv | H20: Agr | I20: Ind | J20: Serv | K20: Agr | L20: Ind | M20: Serv
C21: A | D21: Agr | E21: =+E5/E$15 -> 0.14084507 | F21: =+F5/F$15 -> 0.090909091 | G21: =+G5/G$15 -> 0.21276596 | H21: =+H5/H$15 -> 0.012195122 | I21: =+I5/I$15 -> 0 | J21: =+J5/J$15 -> 0.14545455 | K21: =+K5/K$15 -> 0.037974684 | L21: =+L5/L$15 -> 0.10769231 | M21: =+M5/M$15 -> 0.033333333
C22: A | D22: Ind | E22: =+E6/E$15 -> 0.11267606 | F22: =+F6/F$15 -> 0.054545455 | G22: =+G6/G$15 -> 0.19148936 | H22: =+H6/H$15 -> 0.048780488 | I22: =+I6/I$15 -> 0.04 | J22: =+J6/J$15 -> 0.18181818 | K22: =+K6/K$15 -> 0.012658228 | L22: =+L6/L$15 -> 0.061538462 | M22: =+M6/M$15 -> 0.11666667
C23: A | D23: Serv | E23: =+E7/E$15 -> 0 | F23: =+F7/F$15 -> 0 | G23: =+G7/G$15 -> 0 | H23: =+H7/H$15 -> 0.085365854 | I23: =+I7/I$15 -> 0.08 | J23: =+J7/J$15 -> 0.072727273 | K23: =+K7/K$15 -> 0.088607595 | L23: =+L7/L$15 -> 0.061538462 | M23: =+M7/M$15 -> 0.11666667
C24: B | D24: =+D21 -> Agr | E24: =+E8/E$15 -> 0.12676056 | F24: =+F8/F$15 -> 0.090909091 | G24: =+G8/G$15 -> 0.085106383 | H24: =+H8/H$15 -> 0.085365854 | I24: =+I8/I$15 -> 0.2 | J24: =+J8/J$15 -> 0.16363636 | K24: =+K8/K$15 -> 0.12658228 | L24: =+L8/L$15 -> 0.13846154 | M24: =+M8/M$15 -> 0.15
C25: B | D25: =+D22 -> Ind | E25: =+E9/E$15 -> 0.056338028 | F25: =+F9/F$15 -> 0.036363636 | G25: =+G9/G$15 -> 0.063829787 | H25: =+H9/H$15 -> 0.073170732 | I25: =+I9/I$15 -> 0.14 | J25: =+J9/J$15 -> 0.072727273 | K25: =+K9/K$15 -> 0.11392405 | L25: =+L9/L$15 -> 0.030769231 | M25: =+M9/M$15 -> 0.13333333
C26: B | D26: =+D23 -> Serv | E26: =+E10/E$15 -> 0.084507042 | F26: =+F10/F$15 -> 0.090909091 | G26: =+G10/G$15 -> 0.085106383 | H26: =+H10/H$15 -> 0.012195122 | I26: =+I10/I$15 -> 0.18 | J26: =+J10/J$15 -> 0.036363636 | K26: =+K10/K$15 -> 0.012658228 | L26: =+L10/L$15 -> 0.092307692 | M26: =+M10/M$15 -> 0.016666667
C27: C | D27: =+D24 -> Agr | E27: =+E11/E$15 -> 0.042253521 | F27: =+F11/F$15 -> 0.18181818 | G27: =+G11/G$15 -> 0.17021277 | H27: =+H11/H$15 -> 0.1097561 | I27: =+I11/I$15 -> 0.2 | J27: =+J11/J$15 -> 0 | K27: =+K11/K$15 -> 0.088607595 | L27: =+L11/L$15 -> 0.13846154 | M27: =+M11/M$15 -> 0.13333333
C28: C | D28: =+D25 -> Ind | E28: =+E12/E$15 -> 0.014084507 | F28: =+F12/F$15 -> 0.14545455 | G28: =+G12/G$15 -> 0 | H28: =+H12/H$15 -> 0.1097561 | I28: =+I12/I$15 -> 0 | J28: =+J12/J$15 -> 0 | K28: =+K12/K$15 -> 0.10126582 | L28: =+L12/L$15 -> 0.15384615 | M28: =+M12/M$15 -> 0.016666667
C29: C | D29: =+D26 -> Serv | E29: =+E13/E$15 -> 0.14084507 | F29: =+F13/F$15 -> 0.036363636 | G29: =+G13/G$15 -> 0.085106383 | H29: =+H13/H$15 -> 0.12195122 | I29: =+I13/I$15 -> 0 | J29: =+J13/J$15 -> 0 | K29: =+K13/K$15 -> 0.037974684 | L29: =+L13/L$15 -> 0 | M29: =+M13/M$15 -> 0.11666667
D30: VA | E30: =+E14/E$15 -> 0.28169014 | F30: =+F14/F$15 -> 0.27272727 | G30: =+G14/G$15 -> 0.10638298 | H30: =+H14/H$15 -> 0.34146341 | I30: =+I14/I$15 -> 0.16 | J30: =+J14/J$15 -> 0.32727273 | K30: =+K14/K$15 -> 0.37974684 | L30: =+L14/L$15 -> 0.21538462 | M30: =+M14/M$15 -> 0.16666667
D31: X | E31: =SUM(E21:E30) -> 1 | F31: =SUM(F21:F30) -> 1 | G31: =SUM(G21:G30) -> 1 | H31: =SUM(H21:H30) -> 1 | I31: =SUM(I21:I30) -> 1 | J31: =SUM(J21:J30) -> 1 | K31: =SUM(K21:K30) -> 1 | L31: =SUM(L21:L30) -> 1 | M31: =SUM(M21:M30) -> 1
E34: A | F34: A | G34: A | H34: B | I34: B | J34: B | K34: C | L34: C | M34: C
D35: L | E35: Agr | F35: Ind | G35: Serv | H35: Agr | I35: Ind | J35: Serv | K35: Agr | L35: Ind | M35: Serv
C36: A | D36: Agr | E36: {=+MINVERSE(_xlfn.MUNIT(COUNTA($D$36:$D$44))-E21:M29)} -> 1.3396898 | F36: 0.29313766 | G36: 0.46062081 | H36: 0.20047115 | I36: 0.22471967 | J36: 0.3432924 | K36: 0.21398444 | L36: 0.33876648 | M36: 0.26323813 | N36: {=+MMULT(_xlfn.ANCHORARRAY(E36),N5:N13)} -> 71
C37: A | D37: Ind | E37: 0.33305376 | F37: 1.2588963 | G37: 0.44906572 | H37: 0.24914152 | I37: 0.28508256 | J37: 0.38551433 | K37: 0.19834507 | L37: 0.2922519 | M37: 0.36621325 | N37: 55
C38: A | D38: Serv | E38: 0.16096426 | F38: 0.16098913 | G38: 1.1866305 | H38: 0.2426696 | I38: 0.27162889 | J38: 0.20593716 | K38: 0.23314113 | L38: 0.22869829 | M38: 0.30966204 | N38: 47
C39: B | D39: =+D36 -> Agr | E39: 0.4694894 | F39: 0.42979984 | G39: 0.50026322 | H39: 1.4082652 | I39: 0.59296552 | J39: 0.47360784 | K39: 0.42917418 | L39: 0.50129475 | M39: 0.55237411 | N39: 82
C40: B | D40: =+D37 -> Ind | E40: 0.27827723 | F40: 0.24820394 | G40: 0.33029476 | H40: 0.284956 | I40: 1.3995953 | J40: 0.26778154 | K40: 0.31054186 | L40: 0.25504175 | M40: 0.40329378 | N40: 50
C41: B | D41: =+D38 -> Serv | E41: 0.24935171 | F41: 0.25257975 | G41: 0.28900631 | H41: 0.17116188 | I41: 0.36899675 | J41: 1.2017562 | K41: 0.16782505 | L41: 0.27111308 | M41: 0.21882465 | N41: 55
C42: C | D42: =+D39 -> Agr | E42: 0.35214837 | F42: 0.4808315 | G42: 0.54248305 | H42: 0.42036737 | I42: 0.55309703 | J42: 0.29794582 | K42: 1.3766391 | L42: 0.46591317 | M42: 0.52551987 | N42: 79
C43: C | D43: =+D40 -> Ind | E43: 0.1889523 | F43: 0.33840247 | G43: 0.22055756 | H43: 0.28461936 | I43: 0.19938771 | J43: 0.1723962 | K43: 0.26168767 | L43: 1.3619713 | M43: 0.22783339 | N43: 65
C44: C | D44: =+D41 -> Serv | E44: 0.32278456 | F44: 0.19408334 | G44: 0.29864604 | H44: 0.27809522 | I44: 0.17937872 | J44: 0.16864275 | K44: 0.18317972 | L44: 0.17731814 | M44: 1.3178106 | N44: 60
C46: Demand shock | E46: d_shock | F46: 1-d_shock | G46: FD | H46: fd_max | J46: Supply shock | L46: p_shock | M46: 1-p_shock | N46: X | O46: x_max
...

Sheet IO_sub_model - t+2
E3: A | F3: A | G3: A | H3: B | I3: B | J3: B | K3: C | L3: C | M3: C
D4: Z | E4: Agr | F4: Ind | G4: Serv | H4: Agr | I4: Ind | J4: Serv | K4: Agr | L4: Ind | M4: Serv | N4: FD | O4: X | P4: AX | Q4: X
C5: A | D5: Agr | E5: 10 | F5: 5 | G5: 10 | H5: 1 | I5: 0 | J5: 8 | K5: 3 | L5: 7 | M5: 2 | N5: 25 | O5: =+SUM(E5:N5) -> 71 | P5: {=+MMULT(E21:M29,O5:O13)} -> 46 | Q5: =+P5+N5 -> 71 | R5: =+Q5=O5 -> TRUE
C6: A | D6: Ind | E6: 8 | F6: 3 | G6: 9 | H6: 4 | I6: 2 | J6: 10 | K6: 1 | L6: 4 | M6: 7 | N6: 7 | O6: =+SUM(E6:N6) -> 55 | P6: 48 | Q6: =+P6+N6 -> 55 | R6: =+Q6=O6 -> TRUE
C7: A | D7: Serv | E7: 0 | F7: 0 | G7: 0 | H7: 7 | I7: 4 | J7: 4 | K7: 7 | L7: 4 | M7: 7 | N7: 14 | O7: =+SUM(E7:N7) -> 47 | P7: 33 | Q7: =+P7+N7 -> 47 | R7: =+Q7=O7 -> TRUE
C8: B | D8: =+D5 -> Agr | E8: 9 | F8: 5 | G8: 4 | H8: 7 | I8: 10 | J8: 9 | K8: 10 | L8: 9 | M8: 9 | N8: 10 | O8: =+SUM(E8:N8) -> 82 | P8: 72 | Q8: =+P8+N8 -> 82 | R8: =+Q8=O8 -> TRUE
C9: B | D9: =+D6 -> Ind | E9: 4 | F9: 2 | G9: 3 | H9: 6 | I9: 7 | J9: 4 | K9: 9 | L9: 2 | M9: 8 | N9: 5 | O9: =+SUM(E9:N9) -> 50 | P9: 45 | Q9: =+P9+N9 -> 50 | R9: =+Q9=O9 -> TRUE
C10: B | D10: =+D7 -> Serv | E10: 6 | F10: 5 | G10: 4 | H10: 1 | I10: 9 | J10: 2 | K10: 1 | L10: 6 | M10: 1 | N10: 20 | O10: =+SUM(E10:N10) -> 55 | P10: 35 | Q10: =+P10+N10 -> 55 | R10: =+Q10=O10 -> TRUE
C11: C | D11: =+D8 -> Agr | E11: 3 | F11: 10 | G11: 8 | H11: 9 | I11: 10 | J11: 0 | K11: 7 | L11: 9 | M11: 8 | N11: 15 | O11: =+SUM(E11:N11) -> 79 | P11: 64 | Q11: =+P11+N11 -> 79 | R11: =+Q11=O11 -> TRUE
C12: C | D12: =+D9 -> Ind | E12: 1 | F12: 8 | G12: 0 | H12: 9 | I12: 0 | J12: 0 | K12: 8 | L12: 10 | M12: 1 | N12: 28 | O12: =+SUM(E12:N12) -> 65 | P12: 37 | Q12: =+P12+N12 -> 65 | R12: =+Q12=O12 -> TRUE
C13: C | D13: =+D10 -> Serv | E13: 10 | F13: 2 | G13: 4 | H13: 10 | I13: 0 | J13: 0 | K13: 3 | L13: 0 | M13: 7 | N13: 24 | O13: =+SUM(E13:N13) -> 60 | P13: 36 | Q13: =+P13+N13 -> 60 | R13: =+Q13=O13 -> TRUE
D14: VA | E14: 20 | F14: 15 | G14: 5 | H14: 28 | I14: 8 | J14: 18 | K14: 30 | L14: 14 | M14: 10 | N14: =+SUM(E5:M13) -> 416 | O14: =SUM(O5:O13) -> 564
D15: X | E15: =SUM(E5:E14) -> 71 | F15: =SUM(F5:F14) -> 55 | G15: =SUM(G5:G14) -> 47 | H15: =SUM(H5:H14) -> 82 | I15: =SUM(I5:I14) -> 50 | J15: =SUM(J5:J14) -> 55 | K15: =SUM(K5:K14) -> 79 | L15: =SUM(L5:L14) -> 65 | M15: =SUM(M5:M14) -> 60
E16: {=+TRANSPOSE(O5:O13)} -> 71 | F16: 55 | G16: 47 | H16: 82 | I16: 50 | J16: 55 | K16: 79 | L16: 65 | M16: 60
E17: =+E15-E16 -> 0 | F17: =+F15-F16 -> 0 | G17: =+G15-G16 -> 0 | H17: =+H15-H16 -> 0 | I17: =+I15-I16 -> 0 | J17: =+J15-J16 -> 0 | K17: =+K15-K16 -> 0 | L17: =+L15-L16 -> 0 | M17: =+M15-M16 -> 0
E19: A | F19: A | G19: A | H19: B | I19: B | J19: B | K19: C | L19: C | M19: C
D20: A | E20: Agr | F20: Ind | G20: Serv | H20: Agr | I20: Ind | J20: Serv | K20: Agr | L20: Ind | M20: Serv
C21: A | D21: Agr | E21: =+E5/E$15 -> 0.14084507 | F21: =+F5/F$15 -> 0.090909091 | G21: =+G5/G$15 -> 0.21276596 | H21: =+H5/H$15 -> 0.012195122 | I21: =+I5/I$15 -> 0 | J21: =+J5/J$15 -> 0.14545455 | K21: =+K5/K$15 -> 0.037974684 | L21: =+L5/L$15 -> 0.10769231 | M21: =+M5/M$15 -> 0.033333333
C22: A | D22: Ind | E22: =+E6/E$15 -> 0.11267606 | F22: =+F6/F$15 -> 0.054545455 | G22: =+G6/G$15 -> 0.19148936 | H22: =+H6/H$15 -> 0.048780488 | I22: =+I6/I$15 -> 0.04 | J22: =+J6/J$15 -> 0.18181818 | K22: =+K6/K$15 -> 0.012658228 | L22: =+L6/L$15 -> 0.061538462 | M22: =+M6/M$15 -> 0.11666667
C23: A | D23: Serv | E23: =+E7/E$15 -> 0 | F23: =+F7/F$15 -> 0 | G23: =+G7/G$15 -> 0 | H23: =+H7/H$15 -> 0.085365854 | I23: =+I7/I$15 -> 0.08 | J23: =+J7/J$15 -> 0.072727273 | K23: =+K7/K$15 -> 0.088607595 | L23: =+L7/L$15 -> 0.061538462 | M23: =+M7/M$15 -> 0.11666667
C24: B | D24: =+D21 -> Agr | E24: =+E8/E$15 -> 0.12676056 | F24: =+F8/F$15 -> 0.090909091 | G24: =+G8/G$15 -> 0.085106383 | H24: =+H8/H$15 -> 0.085365854 | I24: =+I8/I$15 -> 0.2 | J24: =+J8/J$15 -> 0.16363636 | K24: =+K8/K$15 -> 0.12658228 | L24: =+L8/L$15 -> 0.13846154 | M24: =+M8/M$15 -> 0.15
C25: B | D25: =+D22 -> Ind | E25: =+E9/E$15 -> 0.056338028 | F25: =+F9/F$15 -> 0.036363636 | G25: =+G9/G$15 -> 0.063829787 | H25: =+H9/H$15 -> 0.073170732 | I25: =+I9/I$15 -> 0.14 | J25: =+J9/J$15 -> 0.072727273 | K25: =+K9/K$15 -> 0.11392405 | L25: =+L9/L$15 -> 0.030769231 | M25: =+M9/M$15 -> 0.13333333
C26: B | D26: =+D23 -> Serv | E26: =+E10/E$15 -> 0.084507042 | F26: =+F10/F$15 -> 0.090909091 | G26: =+G10/G$15 -> 0.085106383 | H26: =+H10/H$15 -> 0.012195122 | I26: =+I10/I$15 -> 0.18 | J26: =+J10/J$15 -> 0.036363636 | K26: =+K10/K$15 -> 0.012658228 | L26: =+L10/L$15 -> 0.092307692 | M26: =+M10/M$15 -> 0.016666667
C27: C | D27: =+D24 -> Agr | E27: =+E11/E$15 -> 0.042253521 | F27: =+F11/F$15 -> 0.18181818 | G27: =+G11/G$15 -> 0.17021277 | H27: =+H11/H$15 -> 0.1097561 | I27: =+I11/I$15 -> 0.2 | J27: =+J11/J$15 -> 0 | K27: =+K11/K$15 -> 0.088607595 | L27: =+L11/L$15 -> 0.13846154 | M27: =+M11/M$15 -> 0.13333333
C28: C | D28: =+D25 -> Ind | E28: =+E12/E$15 -> 0.014084507 | F28: =+F12/F$15 -> 0.14545455 | G28: =+G12/G$15 -> 0 | H28: =+H12/H$15 -> 0.1097561 | I28: =+I12/I$15 -> 0 | J28: =+J12/J$15 -> 0 | K28: =+K12/K$15 -> 0.10126582 | L28: =+L12/L$15 -> 0.15384615 | M28: =+M12/M$15 -> 0.016666667
C29: C | D29: =+D26 -> Serv | E29: =+E13/E$15 -> 0.14084507 | F29: =+F13/F$15 -> 0.036363636 | G29: =+G13/G$15 -> 0.085106383 | H29: =+H13/H$15 -> 0.12195122 | I29: =+I13/I$15 -> 0 | J29: =+J13/J$15 -> 0 | K29: =+K13/K$15 -> 0.037974684 | L29: =+L13/L$15 -> 0 | M29: =+M13/M$15 -> 0.11666667
D30: VA | E30: =+E14/E$15 -> 0.28169014 | F30: =+F14/F$15 -> 0.27272727 | G30: =+G14/G$15 -> 0.10638298 | H30: =+H14/H$15 -> 0.34146341 | I30: =+I14/I$15 -> 0.16 | J30: =+J14/J$15 -> 0.32727273 | K30: =+K14/K$15 -> 0.37974684 | L30: =+L14/L$15 -> 0.21538462 | M30: =+M14/M$15 -> 0.16666667
D31: X | E31: =SUM(E21:E30) -> 1 | F31: =SUM(F21:F30) -> 1 | G31: =SUM(G21:G30) -> 1 | H31: =SUM(H21:H30) -> 1 | I31: =SUM(I21:I30) -> 1 | J31: =SUM(J21:J30) -> 1 | K31: =SUM(K21:K30) -> 1 | L31: =SUM(L21:L30) -> 1 | M31: =SUM(M21:M30) -> 1
E34: A | F34: A | G34: A | H34: B | I34: B | J34: B | K34: C | L34: C | M34: C
D35: L | E35: Agr | F35: Ind | G35: Serv | H35: Agr | I35: Ind | J35: Serv | K35: Agr | L35: Ind | M35: Serv
C36: A | D36: Agr | E36: {=+MINVERSE(_xlfn.MUNIT(COUNTA($D$36:$D$44))-E21:M29)} -> 1.3396898 | F36: 0.29313766 | G36: 0.46062081 | H36: 0.20047115 | I36: 0.22471967 | J36: 0.3432924 | K36: 0.21398444 | L36: 0.33876648 | M36: 0.26323813 | N36: {=+MMULT(_xlfn.ANCHORARRAY(E36),N5:N13)} -> 71
C37: A | D37: Ind | E37: 0.33305376 | F37: 1.2588963 | G37: 0.44906572 | H37: 0.24914152 | I37: 0.28508256 | J37: 0.38551433 | K37: 0.19834507 | L37: 0.2922519 | M37: 0.36621325 | N37: 55
C38: A | D38: Serv | E38: 0.16096426 | F38: 0.16098913 | G38: 1.1866305 | H38: 0.2426696 | I38: 0.27162889 | J38: 0.20593716 | K38: 0.23314113 | L38: 0.22869829 | M38: 0.30966204 | N38: 47
C39: B | D39: =+D36 -> Agr | E39: 0.4694894 | F39: 0.42979984 | G39: 0.50026322 | H39: 1.4082652 | I39: 0.59296552 | J39: 0.47360784 | K39: 0.42917418 | L39: 0.50129475 | M39: 0.55237411 | N39: 82
C40: B | D40: =+D37 -> Ind | E40: 0.27827723 | F40: 0.24820394 | G40: 0.33029476 | H40: 0.284956 | I40: 1.3995953 | J40: 0.26778154 | K40: 0.31054186 | L40: 0.25504175 | M40: 0.40329378 | N40: 50
C41: B | D41: =+D38 -> Serv | E41: 0.24935171 | F41: 0.25257975 | G41: 0.28900631 | H41: 0.17116188 | I41: 0.36899675 | J41: 1.2017562 | K41: 0.16782505 | L41: 0.27111308 | M41: 0.21882465 | N41: 55
C42: C | D42: =+D39 -> Agr | E42: 0.35214837 | F42: 0.4808315 | G42: 0.54248305 | H42: 0.42036737 | I42: 0.55309703 | J42: 0.29794582 | K42: 1.3766391 | L42: 0.46591317 | M42: 0.52551987 | N42: 79
C43: C | D43: =+D40 -> Ind | E43: 0.1889523 | F43: 0.33840247 | G43: 0.22055756 | H43: 0.28461936 | I43: 0.19938771 | J43: 0.1723962 | K43: 0.26168767 | L43: 1.3619713 | M43: 0.22783339 | N43: 65
C44: C | D44: =+D41 -> Serv | E44: 0.32278456 | F44: 0.19408334 | G44: 0.29864604 | H44: 0.27809522 | I44: 0.17937872 | J44: 0.16864275 | K44: 0.18317972 | L44: 0.17731814 | M44: 1.3178106 | N44: 60
C46: Demand shock | E46: d_shock | F46: 1-d_shock | G46: FD | H46: fd_max | J46: Supply shock | L46: p_shock | M46: 1-p_shock | N46: X | O46: x_max
...

Sheet IO_sub_model - t+3
E3: A | F3: A | G3: A | H3: B | I3: B | J3: B | K3: C | L3: C | M3: C
D4: Z | E4: Agr | F4: Ind | G4: Serv | H4: Agr | I4: Ind | J4: Serv | K4: Agr | L4: Ind | M4: Serv | N4: FD | O4: X | P4: AX | Q4: X
C5: A | D5: Agr | E5: 10 | F5: 5 | G5: 10 | H5: 1 | I5: 0 | J5: 8 | K5: 3 | L5: 7 | M5: 2 | N5: 25 | O5: =+SUM(E5:N5) -> 71 | P5: {=+MMULT(E21:M29,O5:O13)} -> 46 | Q5: =+P5+N5 -> 71 | R5: =+Q5=O5 -> TRUE
C6: A | D6: Ind | E6: 8 | F6: 3 | G6: 9 | H6: 4 | I6: 2 | J6: 10 | K6: 1 | L6: 4 | M6: 7 | N6: 7 | O6: =+SUM(E6:N6) -> 55 | P6: 48 | Q6: =+P6+N6 -> 55 | R6: =+Q6=O6 -> TRUE
C7: A | D7: Serv | E7: 0 | F7: 0 | G7: 0 | H7: 7 | I7: 4 | J7: 4 | K7: 7 | L7: 4 | M7: 7 | N7: 14 | O7: =+SUM(E7:N7) -> 47 | P7: 33 | Q7: =+P7+N7 -> 47 | R7: =+Q7=O7 -> TRUE
C8: B | D8: =+D5 -> Agr | E8: 9 | F8: 5 | G8: 4 | H8: 7 | I8: 10 | J8: 9 | K8: 10 | L8: 9 | M8: 9 | N8: 10 | O8: =+SUM(E8:N8) -> 82 | P8: 72 | Q8: =+P8+N8 -> 82 | R8: =+Q8=O8 -> TRUE
C9: B | D9: =+D6 -> Ind | E9: 4 | F9: 2 | G9: 3 | H9: 6 | I9: 7 | J9: 4 | K9: 9 | L9: 2 | M9: 8 | N9: 5 | O9: =+SUM(E9:N9) -> 50 | P9: 45 | Q9: =+P9+N9 -> 50 | R9: =+Q9=O9 -> TRUE
C10: B | D10: =+D7 -> Serv | E10: 6 | F10: 5 | G10: 4 | H10: 1 | I10: 9 | J10: 2 | K10: 1 | L10: 6 | M10: 1 | N10: 20 | O10: =+SUM(E10:N10) -> 55 | P10: 35 | Q10: =+P10+N10 -> 55 | R10: =+Q10=O10 -> TRUE
C11: C | D11: =+D8 -> Agr | E11: 3 | F11: 10 | G11: 8 | H11: 9 | I11: 10 | J11: 0 | K11: 7 | L11: 9 | M11: 8 | N11: 15 | O11: =+SUM(E11:N11) -> 79 | P11: 64 | Q11: =+P11+N11 -> 79 | R11: =+Q11=O11 -> TRUE
C12: C | D12: =+D9 -> Ind | E12: 1 | F12: 8 | G12: 0 | H12: 9 | I12: 0 | J12: 0 | K12: 8 | L12: 10 | M12: 1 | N12: 28 | O12: =+SUM(E12:N12) -> 65 | P12: 37 | Q12: =+P12+N12 -> 65 | R12: =+Q12=O12 -> TRUE
C13: C | D13: =+D10 -> Serv | E13: 10 | F13: 2 | G13: 4 | H13: 10 | I13: 0 | J13: 0 | K13: 3 | L13: 0 | M13: 7 | N13: 24 | O13: =+SUM(E13:N13) -> 60 | P13: 36 | Q13: =+P13+N13 -> 60 | R13: =+Q13=O13 -> TRUE
D14: VA | E14: 20 | F14: 15 | G14: 5 | H14: 28 | I14: 8 | J14: 18 | K14: 30 | L14: 14 | M14: 10 | N14: =+SUM(E5:M13) -> 416 | O14: =SUM(O5:O13) -> 564
D15: X | E15: =SUM(E5:E14) -> 71 | F15: =SUM(F5:F14) -> 55 | G15: =SUM(G5:G14) -> 47 | H15: =SUM(H5:H14) -> 82 | I15: =SUM(I5:I14) -> 50 | J15: =SUM(J5:J14) -> 55 | K15: =SUM(K5:K14) -> 79 | L15: =SUM(L5:L14) -> 65 | M15: =SUM(M5:M14) -> 60
E16: {=+TRANSPOSE(O5:O13)} -> 71 | F16: 55 | G16: 47 | H16: 82 | I16: 50 | J16: 55 | K16: 79 | L16: 65 | M16: 60
E17: =+E15-E16 -> 0 | F17: =+F15-F16 -> 0 | G17: =+G15-G16 -> 0 | H17: =+H15-H16 -> 0 | I17: =+I15-I16 -> 0 | J17: =+J15-J16 -> 0 | K17: =+K15-K16 -> 0 | L17: =+L15-L16 -> 0 | M17: =+M15-M16 -> 0
E19: A | F19: A | G19: A | H19: B | I19: B | J19: B | K19: C | L19: C | M19: C
D20: A | E20: Agr | F20: Ind | G20: Serv | H20: Agr | I20: Ind | J20: Serv | K20: Agr | L20: Ind | M20: Serv
C21: A | D21: Agr | E21: =+E5/E$15 -> 0.14084507 | F21: =+F5/F$15 -> 0.090909091 | G21: =+G5/G$15 -> 0.21276596 | H21: =+H5/H$15 -> 0.012195122 | I21: =+I5/I$15 -> 0 | J21: =+J5/J$15 -> 0.14545455 | K21: =+K5/K$15 -> 0.037974684 | L21: =+L5/L$15 -> 0.10769231 | M21: =+M5/M$15 -> 0.033333333
C22: A | D22: Ind | E22: =+E6/E$15 -> 0.11267606 | F22: =+F6/F$15 -> 0.054545455 | G22: =+G6/G$15 -> 0.19148936 | H22: =+H6/H$15 -> 0.048780488 | I22: =+I6/I$15 -> 0.04 | J22: =+J6/J$15 -> 0.18181818 | K22: =+K6/K$15 -> 0.012658228 | L22: =+L6/L$15 -> 0.061538462 | M22: =+M6/M$15 -> 0.11666667
C23: A | D23: Serv | E23: =+E7/E$15 -> 0 | F23: =+F7/F$15 -> 0 | G23: =+G7/G$15 -> 0 | H23: =+H7/H$15 -> 0.085365854 | I23: =+I7/I$15 -> 0.08 | J23: =+J7/J$15 -> 0.072727273 | K23: =+K7/K$15 -> 0.088607595 | L23: =+L7/L$15 -> 0.061538462 | M23: =+M7/M$15 -> 0.11666667
C24: B | D24: =+D21 -> Agr | E24: =+E8/E$15 -> 0.12676056 | F24: =+F8/F$15 -> 0.090909091 | G24: =+G8/G$15 -> 0.085106383 | H24: =+H8/H$15 -> 0.085365854 | I24: =+I8/I$15 -> 0.2 | J24: =+J8/J$15 -> 0.16363636 | K24: =+K8/K$15 -> 0.12658228 | L24: =+L8/L$15 -> 0.13846154 | M24: =+M8/M$15 -> 0.15
C25: B | D25: =+D22 -> Ind | E25: =+E9/E$15 -> 0.056338028 | F25: =+F9/F$15 -> 0.036363636 | G25: =+G9/G$15 -> 0.063829787 | H25: =+H9/H$15 -> 0.073170732 | I25: =+I9/I$15 -> 0.14 | J25: =+J9/J$15 -> 0.072727273 | K25: =+K9/K$15 -> 0.11392405 | L25: =+L9/L$15 -> 0.030769231 | M25: =+M9/M$15 -> 0.13333333
C26: B | D26: =+D23 -> Serv | E26: =+E10/E$15 -> 0.084507042 | F26: =+F10/F$15 -> 0.090909091 | G26: =+G10/G$15 -> 0.085106383 | H26: =+H10/H$15 -> 0.012195122 | I26: =+I10/I$15 -> 0.18 | J26: =+J10/J$15 -> 0.036363636 | K26: =+K10/K$15 -> 0.012658228 | L26: =+L10/L$15 -> 0.092307692 | M26: =+M10/M$15 -> 0.016666667
C27: C | D27: =+D24 -> Agr | E27: =+E11/E$15 -> 0.042253521 | F27: =+F11/F$15 -> 0.18181818 | G27: =+G11/G$15 -> 0.17021277 | H27: =+H11/H$15 -> 0.1097561 | I27: =+I11/I$15 -> 0.2 | J27: =+J11/J$15 -> 0 | K27: =+K11/K$15 -> 0.088607595 | L27: =+L11/L$15 -> 0.13846154 | M27: =+M11/M$15 -> 0.13333333
C28: C | D28: =+D25 -> Ind | E28: =+E12/E$15 -> 0.014084507 | F28: =+F12/F$15 -> 0.14545455 | G28: =+G12/G$15 -> 0 | H28: =+H12/H$15 -> 0.1097561 | I28: =+I12/I$15 -> 0 | J28: =+J12/J$15 -> 0 | K28: =+K12/K$15 -> 0.10126582 | L28: =+L12/L$15 -> 0.15384615 | M28: =+M12/M$15 -> 0.016666667
C29: C | D29: =+D26 -> Serv | E29: =+E13/E$15 -> 0.14084507 | F29: =+F13/F$15 -> 0.036363636 | G29: =+G13/G$15 -> 0.085106383 | H29: =+H13/H$15 -> 0.12195122 | I29: =+I13/I$15 -> 0 | J29: =+J13/J$15 -> 0 | K29: =+K13/K$15 -> 0.037974684 | L29: =+L13/L$15 -> 0 | M29: =+M13/M$15 -> 0.11666667
D30: VA | E30: =+E14/E$15 -> 0.28169014 | F30: =+F14/F$15 -> 0.27272727 | G30: =+G14/G$15 -> 0.10638298 | H30: =+H14/H$15 -> 0.34146341 | I30: =+I14/I$15 -> 0.16 | J30: =+J14/J$15 -> 0.32727273 | K30: =+K14/K$15 -> 0.37974684 | L30: =+L14/L$15 -> 0.21538462 | M30: =+M14/M$15 -> 0.16666667
D31: X | E31: =SUM(E21:E30) -> 1 | F31: =SUM(F21:F30) -> 1 | G31: =SUM(G21:G30) -> 1 | H31: =SUM(H21:H30) -> 1 | I31: =SUM(I21:I30) -> 1 | J31: =SUM(J21:J30) -> 1 | K31: =SUM(K21:K30) -> 1 | L31: =SUM(L21:L30) -> 1 | M31: =SUM(M21:M30) -> 1
E34: A | F34: A | G34: A | H34: B | I34: B | J34: B | K34: C | L34: C | M34: C
D35: L | E35: Agr | F35: Ind | G35: Serv | H35: Agr | I35: Ind | J35: Serv | K35: Agr | L35: Ind | M35: Serv
C36: A | D36: Agr | E36: {=+MINVERSE(_xlfn.MUNIT(COUNTA($D$36:$D$44))-E21:M29)} -> 1.3396898 | F36: 0.29313766 | G36: 0.46062081 | H36: 0.20047115 | I36: 0.22471967 | J36: 0.3432924 | K36: 0.21398444 | L36: 0.33876648 | M36: 0.26323813 | N36: {=+MMULT(_xlfn.ANCHORARRAY(E36),N5:N13)} -> 71
C37: A | D37: Ind | E37: 0.33305376 | F37: 1.2588963 | G37: 0.44906572 | H37: 0.24914152 | I37: 0.28508256 | J37: 0.38551433 | K37: 0.19834507 | L37: 0.2922519 | M37: 0.36621325 | N37: 55
C38: A | D38: Serv | E38: 0.16096426 | F38: 0.16098913 | G38: 1.1866305 | H38: 0.2426696 | I38: 0.27162889 | J38: 0.20593716 | K38: 0.23314113 | L38: 0.22869829 | M38: 0.30966204 | N38: 47
C39: B | D39: =+D36 -> Agr | E39: 0.4694894 | F39: 0.42979984 | G39: 0.50026322 | H39: 1.4082652 | I39: 0.59296552 | J39: 0.47360784 | K39: 0.42917418 | L39: 0.50129475 | M39: 0.55237411 | N39: 82
C40: B | D40: =+D37 -> Ind | E40: 0.27827723 | F40: 0.24820394 | G40: 0.33029476 | H40: 0.284956 | I40: 1.3995953 | J40: 0.26778154 | K40: 0.31054186 | L40: 0.25504175 | M40: 0.40329378 | N40: 50
C41: B | D41: =+D38 -> Serv | E41: 0.24935171 | F41: 0.25257975 | G41: 0.28900631 | H41: 0.17116188 | I41: 0.36899675 | J41: 1.2017562 | K41: 0.16782505 | L41: 0.27111308 | M41: 0.21882465 | N41: 55
C42: C | D42: =+D39 -> Agr | E42: 0.35214837 | F42: 0.4808315 | G42: 0.54248305 | H42: 0.42036737 | I42: 0.55309703 | J42: 0.29794582 | K42: 1.3766391 | L42: 0.46591317 | M42: 0.52551987 | N42: 79
C43: C | D43: =+D40 -> Ind | E43: 0.1889523 | F43: 0.33840247 | G43: 0.22055756 | H43: 0.28461936 | I43: 0.19938771 | J43: 0.1723962 | K43: 0.26168767 | L43: 1.3619713 | M43: 0.22783339 | N43: 65
C44: C | D44: =+D41 -> Serv | E44: 0.32278456 | F44: 0.19408334 | G44: 0.29864604 | H44: 0.27809522 | I44: 0.17937872 | J44: 0.16864275 | K44: 0.18317972 | L44: 0.17731814 | M44: 1.3178106 | N44: 60
C46: Demand shock | E46: d_shock | F46: 1-d_shock | G46: FD | H46: fd_max | J46: Supply shock | L46: p_shock | M46: 1-p_shock | N46: X | O46: x_max
...

Sheet IO_sub_model (2)
E3: A | F3: A | G3: A | H3: B | I3: B | J3: B | K3: C | L3: C | M3: C
D4: Z | E4: Agr | F4: Ind | G4: Serv | H4: Agr | I4: Ind | J4: Serv | K4: Agr | L4: Ind | M4: Serv | N4: FD_implied | O4: X_s | P4: AX | Q4: X
C5: A | D5: Agr | E5: =+IO_sub_model!E150 -> 8 | F5: =+IO_sub_model!F150 -> 4 | G5: =+IO_sub_model!G150 -> 8 | H5: =+IO_sub_model!H150 -> 0.8 | I5: =+IO_sub_model!I150 -> 0 | J5: =+IO_sub_model!J150 -> 6.4 | K5: =+IO_sub_model!K150 -> 2.4 | L5: =+IO_sub_model!L150 -> 5.6 | M5: =+IO_sub_model!M150 -> 1.6 | N5: =+O5-SUM(E5:M5) -> 30.610989 | O5: {=+TRANSPOSE(_xlfn.ANCHORARRAY(E15))} -> 67.410989 | P5: {=+MMULT(E21:M29,O5:O13)} -> 36.8 | Q5: =+P5+N5 -> 67.410989 | R5: =+Q5=O5 -> TRUE
C6: A | D6: Ind | E6: =+IO_sub_model!E151 -> 7.4164706 | F6: =+IO_sub_model!F151 -> 3.6423529 | G6: =+IO_sub_model!G151 -> 8.2164706 | H6: =+IO_sub_model!H151 -> 4.6682353 | I6: =+IO_sub_model!I151 -> 1.8258824 | J6: =+IO_sub_model!J151 -> 9.1294118 | K6: =+IO_sub_model!K151 -> 1.8164706 | L6: =+IO_sub_model!L151 -> 4.7811765 | M6: =+IO_sub_model!M151 -> 6.5035294 | N6: =+O6-SUM(E6:M6) -> 4.2197802 | O6: 52.21978 | P6: 48 | Q6: =+P6+N6 -> 52.21978 | R6: =+Q6=O6 -> TRUE
C7: A | D7: Serv | E7: =+IO_sub_model!E152 -> 1.0153846 | F7: =+IO_sub_model!F152 -> 0.44423077 | G7: =+IO_sub_model!G152 -> 0.50769231 | H7: =+IO_sub_model!H152 -> 6.7423077 | I7: =+IO_sub_model!I152 -> 4.025 | J7: =+IO_sub_model!J152 -> 3.5807692 | K7: =+IO_sub_model!K152 -> 6.2980769 | L7: =+IO_sub_model!L152 -> 3.8346154 | M7: =+IO_sub_model!M152 -> 6.5519231 | N7: =+O7-SUM(E7:M7) -> 11.624176 | O7: 44.624176 | P7: 33 | Q7: =+P7+N7 -> 44.624176 | R7: =+Q7=O7 -> TRUE
C8: B | D8: =+D5 -> Agr | E8: =+IO_sub_model!E153 -> 8.9406593 | F8: =+IO_sub_model!F153 -> 5.5824176 | G8: =+IO_sub_model!G153 -> 4.9406593 | H8: =+IO_sub_model!H153 -> 6.9450549 | I8: =+IO_sub_model!I153 -> 9.5824176 | J8: =+IO_sub_model!J153 -> 8.5450549 | K8: =+IO_sub_model!K153 -> 9.5824176 | L8: =+IO_sub_model!L153 -> 9.178022 | M8: =+IO_sub_model!M153 -> 8.7032967 | N8: =+O8-SUM(E8:M8) -> 5.8549451 | O8: 77.854945 | P8: 72 | Q8: =+P8+N8 -> 77.854945 | R8: =+Q8=O8 -> TRUE
C9: B | D9: =+D6 -> Ind | E9: =+IO_sub_model!E154 -> 4 | F9: =+IO_sub_model!F154 -> 2 | G9: =+IO_sub_model!G154 -> 3 | H9: =+IO_sub_model!H154 -> 6 | I9: =+IO_sub_model!I154 -> 7 | J9: =+IO_sub_model!J154 -> 4 | K9: =+IO_sub_model!K154 -> 9 | L9: =+IO_sub_model!L154 -> 2 | M9: =+IO_sub_model!M154 -> 8 | N9: =+O9-SUM(E9:M9) -> 2.4725275 | O9: 47.472527 | P9: 45 | Q9: =+P9+N9 -> 47.472527 | R9: =+Q9=O9 -> TRUE
C10: B | D10: =+D7 -> Serv | E10: =+IO_sub_model!E155 -> 5.8769231 | F10: =+IO_sub_model!F155 -> 4.4711538 | G10: =+IO_sub_model!G155 -> 3.7384615 | H10: =+IO_sub_model!H155 -> 2.0115385 | I10: =+IO_sub_model!I155 -> 8.075 | J10: =+IO_sub_model!J155 -> 2.0038462 | K10: =+IO_sub_model!K155 -> 1.5403846 | L10: =+IO_sub_model!L155 -> 5.4730769 | M10: =+IO_sub_model!M155 -> 1.8096154 | N10: =+O10-SUM(E10:M10) -> 17.21978 | O10: 52.21978 | P10: 35 | Q10: =+P10+N10 -> 52.21978 | R10: =+Q10=O10 -> TRUE
C11: C | D11: =+D8 -> Agr | E11: =+IO_sub_model!E156 -> 3.9472527 | F11: =+IO_sub_model!F156 -> 9.4065934 | G11: =+IO_sub_model!G156 -> 7.9472527 | H11: =+IO_sub_model!H156 -> 8.3956044 | I11: =+IO_sub_model!I156 -> 9.4065934 | J11: =+IO_sub_model!J156 -> 1.1956044 | K11: =+IO_sub_model!K156 -> 7.0065934 | L11: =+IO_sub_model!L156 -> 8.9582418 | M11: =+IO_sub_model!M156 -> 7.7362637 | N11: =+O11-SUM(E11:M11) -> 11.006593 | O11: 75.006593 | P11: 64 | Q11: =+P11+N11 -> 75.006593 | R11: =+Q11=O11 -> TRUE
C12: C | D12: =+D9 -> Ind | E12: =+IO_sub_model!E157 -> 1.5835294 | F12: =+IO_sub_model!F157 -> 7.3576471 | G12: =+IO_sub_model!G157 -> 0.78352941 | H12: =+IO_sub_model!H157 -> 8.3317647 | I12: =+IO_sub_model!I157 -> 0.17411765 | J12: =+IO_sub_model!J157 -> 0.87058824 | K12: =+IO_sub_model!K157 -> 7.1835294 | L12: =+IO_sub_model!L157 -> 9.2188235 | M12: =+IO_sub_model!M157 -> 1.4964706 | N12: =+O12-SUM(E12:M12) -> 24.714286 | O12: 61.714286 | P12: 37 | Q12: =+P12+N12 -> 61.714286 | R12: =+Q12=O12 -> TRUE
C13: C | D13: =+D10 -> Serv | E13: =+IO_sub_model!E158 -> 9.1076923 | F13: =+IO_sub_model!F158 -> 2.0846154 | G13: =+IO_sub_model!G158 -> 3.7538462 | H13: =+IO_sub_model!H158 -> 9.2461538 | I13: =+IO_sub_model!I158 -> 0.9 | J13: =+IO_sub_model!J158 -> 0.41538462 | K13: =+IO_sub_model!K158 -> 3.1615385 | L13: =+IO_sub_model!L158 -> 0.69230769 | M13: =+IO_sub_model!M158 -> 6.6384615 | N13: =+O13-SUM(E13:M13) -> 20.967033 | O13: 56.967033 | P13: 36 | Q13: =+P13+N13 -> 56.967033 | R13: =+Q13=O13 -> TRUE
D14: VA | E14: =+E15-SUM(E5:E13) -> 17.523077 | F14: =+F15-SUM(F5:F13) -> 13.230769 | G14: =+G15-SUM(G5:G13) -> 3.7362637 | H14: =+H15-SUM(H5:H13) -> 24.714286 | I14: =+I15-SUM(I5:I13) -> 6.4835165 | J14: =+J15-SUM(J5:J13) -> 16.079121 | K14: =+K15-SUM(K5:K13) -> 27.017582 | L14: =+L15-SUM(L5:L13) -> 11.978022 | M14: =+M15-SUM(M5:M13) -> 7.9274725 | N14: =+SUM(E5:M13) -> 406.8
D15: X | E15: {=+IO_sub_model!E184:M184} -> 67.410989 | F15: 52.21978 | G15: 44.624176 | H15: 77.854945 | I15: 47.472527 | J15: 52.21978 | K15: 75.006593 | L15: 61.714286 | M15: 56.967033
E16: {=+TRANSPOSE(O5:O13)} -> 67.410989 | F16: 52.21978 | G16: 44.624176 | H16: 77.854945 | I16: 47.472527 | J16: 52.21978 | K16: 75.006593 | L16: 61.714286 | M16: 56.967033
E17: =+E15-E16 -> 0 | F17: =+F15-F16 -> 0 | G17: =+G15-G16 -> 0 | H17: =+H15-H16 -> 0 | I17: =+I15-I16 -> 0 | J17: =+J15-J16 -> 0 | K17: =+K15-K16 -> 0 | L17: =+L15-L16 -> 0 | M17: =+M15-M16 -> 0
E19: A | F19: A | G19: A | H19: B | I19: B | J19: B | K19: C | L19: C | M19: C
D20: A | E20: Agr | F20: Ind | G20: Serv | H20: Agr | I20: Ind | J20: Serv | K20: Agr | L20: Ind | M20: Serv
C21: A | D21: Agr | E21: =+IO_sub_model!E200 -> 0.11867501 | F21: =+IO_sub_model!F200 -> 0.076599327 | G21: =+IO_sub_model!G200 -> 0.17927502 | H21: =+IO_sub_model!H200 -> 0.010275519 | I21: =+IO_sub_model!I200 -> 0 | J21: =+IO_sub_model!J200 -> 0.12255892 | K21: =+IO_sub_model!K200 -> 0.031997187 | L21: =+IO_sub_model!L200 -> 0.090740741 | M21: =+IO_sub_model!M200 -> 0.02808642
C22: A | D22: Ind | E22: =+IO_sub_model!E201 -> 0.11001872 | F22: =+IO_sub_model!F201 -> 0.069750446 | G22: =+IO_sub_model!G201 -> 0.18412599 | H22: =+IO_sub_model!H201 -> 0.059960678 | I22: =+IO_sub_model!I201 -> 0.038461874 | J22: =+IO_sub_model!J201 -> 0.1748267 | K22: =+IO_sub_model!K201 -> 0.024217479 | L22: =+IO_sub_model!L201 -> 0.077472767 | M22: =+IO_sub_model!M201 -> 0.11416304
C23: A | D23: Serv | E23: =+IO_sub_model!E202 -> 0.015062598 | F23: =+IO_sub_model!F202 -> 0.0085069444 | G23: =+IO_sub_model!G202 -> 0.011377069 | H23: =+IO_sub_model!H202 -> 0.086600892 | I23: =+IO_sub_model!I202 -> 0.08478588 | J23: =+IO_sub_model!J202 -> 0.068571128 | K23: =+IO_sub_model!K202 -> 0.083966977 | L23: =+IO_sub_model!L202 -> 0.062134972 | M23: =+IO_sub_model!M202 -> 0.11501254
C24: B | D24: =+D21 -> Agr | E24: =+IO_sub_model!E203 -> 0.13262911 | F24: =+IO_sub_model!F203 -> 0.10690236 | G24: =+IO_sub_model!G203 -> 0.1107171 | H24: =+IO_sub_model!H203 -> 0.089205059 | I24: =+IO_sub_model!I203 -> 0.20185185 | J24: =+IO_sub_model!J203 -> 0.16363636 | K24: =+IO_sub_model!K203 -> 0.12775434 | L24: =+IO_sub_model!L203 -> 0.14871795 | M24: =+IO_sub_model!M203 -> 0.15277778
C25: B | D25: =+D22 -> Ind | E25: =+IO_sub_model!E204 -> 0.059337507 | F25: =+IO_sub_model!F204 -> 0.038299663 | G25: =+IO_sub_model!G204 -> 0.067228132 | H25: =+IO_sub_model!H204 -> 0.077066396 | I25: =+IO_sub_model!I204 -> 0.1474537 | J25: =+IO_sub_model!J204 -> 0.076599327 | K25: =+IO_sub_model!K204 -> 0.11998945 | L25: =+IO_sub_model!L204 -> 0.032407407 | M25: =+IO_sub_model!M204 -> 0.1404321
C26: B | D26: =+D23 -> Serv | E26: =+IO_sub_model!E205 -> 0.08718049 | F26: =+IO_sub_model!F205 -> 0.085621843 | G26: =+IO_sub_model!G205 -> 0.083776596 | H26: =+IO_sub_model!H205 -> 0.025837003 | I26: =+IO_sub_model!I205 -> 0.17009838 | J26: =+IO_sub_model!J205 -> 0.038373316 | K26: =+IO_sub_model!K205 -> 0.020536656 | L26: =+IO_sub_model!L205 -> 0.088684117 | M26: =+IO_sub_model!M205 -> 0.031766011
C27: C | D27: =+D24 -> Agr | E27: =+IO_sub_model!E206 -> 0.058555034 | F27: =+IO_sub_model!F206 -> 0.18013468 | G27: =+IO_sub_model!G206 -> 0.17809299 | H27: =+IO_sub_model!H206 -> 0.1078365 | I27: =+IO_sub_model!I206 -> 0.19814815 | J27: =+IO_sub_model!J206 -> 0.022895623 | K27: =+IO_sub_model!K206 -> 0.093413033 | L27: =+IO_sub_model!L206 -> 0.1451567 | M27: =+IO_sub_model!M206 -> 0.13580247
C28: C | D28: =+D25 -> Ind | E28: =+IO_sub_model!E207 -> 0.023490672 | F28: =+IO_sub_model!F207 -> 0.1408977 | G28: =+IO_sub_model!G207 -> 0.017558406 | H28: =+IO_sub_model!H207 -> 0.10701651 | I28: =+IO_sub_model!I207 -> 0.003667756 | J28: =+IO_sub_model!J207 -> 0.016671618 | K28: =+IO_sub_model!K207 -> 0.095771973 | L28: =+IO_sub_model!L207 -> 0.14937908 | M28: =+IO_sub_model!M207 -> 0.026269063
C29: C | D29: =+D26 -> Serv | E29: =+IO_sub_model!E208 -> 0.13510694 | F29: =+IO_sub_model!F208 -> 0.039920034 | G29: =+IO_sub_model!G208 -> 0.084121355 | H29: =+IO_sub_model!H208 -> 0.11876129 | I29: =+IO_sub_model!I208 -> 0.018958333 | J29: =+IO_sub_model!J208 -> 0.0079545455 | K29: =+IO_sub_model!K208 -> 0.042150141 | L29: =+IO_sub_model!L208 -> 0.011217949 | M29: =+IO_sub_model!M208 -> 0.11653164
D30: VA | E30: =+E14/E$15 -> 0.25994392 | F30: =+F14/F$15 -> 0.253367 | G30: =+G14/G$15 -> 0.083727344 | H30: =+H14/H$15 -> 0.31744015 | I30: =+I14/I$15 -> 0.13657407 | J30: =+J14/J$15 -> 0.30791246 | K30: =+K14/K$15 -> 0.36020277 | L30: =+L14/L$15 -> 0.19408832 | M30: =+M14/M$15 -> 0.13915895
D31: X | E31: =SUM(E21:E30) -> 1 | F31: =SUM(F21:F30) -> 1 | G31: =SUM(G21:G30) -> 1 | H31: =SUM(H21:H30) -> 1 | I31: =SUM(I21:I30) -> 1 | J31: =SUM(J21:J30) -> 1 | K31: =SUM(K21:K30) -> 1 | L31: =SUM(L21:L30) -> 1 | M31: =SUM(M21:M30) -> 1
E34: A | F34: A | G34: A | H34: B | I34: B | J34: B | K34: C | L34: C | M34: C
D35: L | E35: Agr | F35: Ind | G35: Serv | H35: Agr | I35: Ind | J35: Serv | K35: Agr | L35: Ind | M35: Serv
C36: A | D36: Agr | E36: {=+MINVERSE(_xlfn.MUNIT(COUNTA($D$36:$D$44))-E21:M29)} -> 1.3054594 | F36: 0.26348041 | G36: 0.40818899 | H36: 0.18774468 | I36: 0.20970152 | J36: 0.30395018 | K36: 0.19529658 | L36: 0.30212832 | M36: 0.24442071
C37: A | D37: Ind | E37: 0.36949669 | F37: 1.3141597 | G37: 0.48824443 | H37: 0.30057826 | I37: 0.32908342 | J37: 0.41349827 | K37: 0.24480938 | L37: 0.35018544 | M37: 0.41232494
C38: A | D38: Serv | E38: 0.20843503 | F38: 0.1987327 | G38: 1.2383543 | H38: 0.27267592 | I38: 0.31212778 | J38: 0.23579115 | K38: 0.25633318 | L38: 0.26324635 | M38: 0.34599544
C39: B | D39: =+D36 -> Agr | E39: 0.53718634 | F39: 0.50426203 | G39: 0.59853673 | H39: 1.4734649 | I39: 0.66712378 | J39: 0.53350191 | K39: 0.48621674 | L39: 0.57691174 | M39: 0.63208244
C40: B | D40: =+D37 -> Ind | E40: 0.32345808 | F40: 0.29054865 | G40: 0.3834799 | H40: 0.32884204 | I40: 1.4579858 | J40: 0.3109533 | K40: 0.35427379 | L40: 0.30097431 | M40: 0.46095908
C41: B | D41: =+D38 -> Serv | E41: 0.28316784 | F41: 0.27598054 | G41: 0.32235897 | H41: 0.21436035 | I41: 0.39465155 | J41: 1.2292613 | K41: 0.2015136 | L41: 0.29751843 | M41: 0.27045317
C42: C | D42: =+D39 -> Agr | E42: 0.42917593 | F42: 0.54016576 | G42: 0.6238704 | H42: 0.4735028 | I42: 0.6220124 | J42: 0.3758766 | K42: 1.4325222 | L42: 0.53852778 | M42: 0.59514511
C43: C | D43: =+D40 -> Ind | E43: 0.23494841 | F43: 0.36694278 | G43: 0.28133164 | H43: 0.31423228 | I43: 0.24195297 | J43: 0.22273645 | K43: 0.28572124 | L43: 1.3944447 | M43: 0.27770135
C44: C | D44: =+D41 -> Serv | E44: 0.34134543 | F44: 0.22553363 | G44: 0.32732522 | H44: 0.30189633 | I44: 0.23392646 | J44: 0.19783658 | K44: 0.21208586 | L44: 0.2171814 | M44: 1.3500727
C46: Demand shock | E46: d_shock | F46: 1-d_shock | G46: FD | H46: fd_max | J46: Supply shock | L46: p_shock | M46: 1-p_shock | N46: X | O46: x_max
...

Sheet IO_sub_model (3)
E3: A | F3: A | G3: A | H3: B | I3: B | J3: B | K3: C | L3: C | M3: C
D4: Z | E4: Agr | F4: Ind | G4: Serv | H4: Agr | I4: Ind | J4: Serv | K4: Agr | L4: Ind | M4: Serv | N4: FD | O4: X | P4: AX | Q4: X
C5: A | D5: Agr | E5: {=+'IO_sub_model (2)'!E150:M158} -> 7.5956044 | F5: 4.0303297 | G5: 7.8513846 | H5: 0.95720879 | I5: 0.23252747 | J5: 6.2741319 | K5: 2.5112088 | L5: 5.6075824 | M5: 1.740022 | N5: =+O5-SUM(E5:M5) -> 27.203401 | O5: {=+TRANSPOSE(_xlfn.ANCHORARRAY(E15))} -> 64.003401 | P5: {=+MMULT(E21:M29,O5:O13)} -> 36.8 | Q5: =+P5+N5 -> 64.003401 | R5: =+Q5=O5 -> TRUE
C6: A | D6: Ind | E6: 7.0415721 | F6: 3.7278311 | G6: 8.0499913 | H6: 4.8262851 | I6: 1.9202291 | J6: 8.9582603 | K6: 2.0979372 | L6: 4.8713024 | M6: 6.5065914 | N6: =+O6-SUM(E6:M6) -> 4.5827364 | O6: 52.582736 | P6: 48 | Q6: =+P6+N6 -> 52.582736 | R6: =+Q6=O6 -> TRUE
C7: A | D7: Serv | E7: 0.96405748 | F7: 0.55446746 | G7: 0.63367709 | H7: 6.7426965 | I7: 4.067967 | J7: 3.5134996 | K7: 6.1882291 | L7: 3.8303381 | M7: 6.5050676 | N7: =+O7-SUM(E7:M7) -> 11.934338 | O7: 44.934338 | P7: 33 | Q7: =+P7+N7 -> 44.934338 | R7: =+Q7=O7 -> TRUE
C8: B | D8: =+D5 -> Agr | E8: 8.4887139 | F8: 5.7551745 | G8: 5.1913513 | H8: 6.9806895 | I8: 9.5529767 | J8: 8.4998104 | K8: 9.5529767 | L8: 9.2827593 | M8: 8.6955476 | N8: =+O8-SUM(E8:M8) -> 6.3960797 | O8: 78.39608 | P8: 72 | Q8: =+P8+N8 -> 78.39608 | R8: =+Q8=O8 -> TRUE
C9: B | D9: =+D6 -> Ind | E9: 3.7978022 | F9: 2.1516484 | G9: 3.0816568 | H9: 6.0661031 | I9: 6.8211327 | J9: 4.0699915 | K9: 8.8950127 | L9: 2.2099746 | M9: 7.9066779 | N9: =+O9-SUM(E9:M9) -> 2.8024876 | O9: 47.802488 | P9: 45 | Q9: =+P9+N9 -> 47.802488 | R9: =+Q9=O9 -> TRUE
C10: B | D10: =+D7 -> Serv | E10: 5.5798478 | F10: 4.3858737 | G10: 3.7103235 | H10: 2.2717444 | I10: 7.9281768 | J10: 2.0231822 | K10: 1.6836729 | L10: 5.3974648 | M10: 2.0197137 | N10: =+O10-SUM(E10:M10) -> 17.582736 | O10: 52.582736 | P10: 35 | Q10: =+P10+N10 -> 52.582736 | R10: =+Q10=O10 -> TRUE
C11: C | D11: =+D8 -> Agr | E11: 3.7477213 | F11: 9.3354909 | G11: 7.9903587 | H11: 8.3149475 | I11: 9.3354909 | J11: 1.4789035 | K11: 7.0568096 | L11: 9.0109021 | M11: 7.7293757 | N11: =+O11-SUM(E11:M11) -> 11.52793 | O11: 75.52793 | P11: 64 | Q11: =+P11+N11 -> 75.52793 | R11: =+Q11=O11 -> TRUE
C12: C | D12: =+D9 -> Ind | E12: 1.5034829 | F12: 7.1935365 | G12: 0.93575111 | H12: 8.2143273 | I12: 0.30918761 | J12: 1.0503806 | K12: 7.108149 | L12: 9.0085886 | M12: 1.6765964 | N12: =+O12-SUM(E12:M12) -> 25.143234 | O12: 62.143234 | P12: 37 | Q12: =+P12+N12 -> 62.143234 | R12: =+Q12=O12 -> TRUE
C13: C | D13: =+D10 -> Serv | E13: 8.6473035 | F13: 2.1239945 | G13: 3.7295259 | H13: 9.1509936 | I13: 1.1233367 | J13: 0.51846308 | K13: 3.229197 | L13: 0.86410513 | M13: 6.6130808 | N13: =+O13-SUM(E13:M13) -> 21.362985 | O13: 57.362985 | P13: 36 | Q13: =+P13+N13 -> 57.362985 | R13: =+Q13=O13 -> TRUE
D14: VA | E14: =+E15-SUM(E5:E13) -> 16.637295 | F14: =+F15-SUM(F5:F13) -> 13.32439 | G14: =+G15-SUM(G5:G13) -> 3.7603181 | H14: =+H15-SUM(H5:H13) -> 24.871084 | I14: =+I15-SUM(I5:I13) -> 6.5114626 | J14: =+J15-SUM(J5:J13) -> 16.196113 | K14: =+K15-SUM(K5:K13) -> 27.204738 | L14: =+L15-SUM(L5:L13) -> 12.060216 | M14: =+M15-SUM(M5:M13) -> 7.970312 | N14: =+SUM(E5:M13) -> 406.8
D15: X | E15: {=+'IO_sub_model (2)'!E184:M184} -> 64.003401 | F15: 52.582736 | G15: 44.934338 | H15: 78.39608 | I15: 47.802488 | J15: 52.582736 | K15: 75.52793 | L15: 62.143234 | M15: 57.362985
E16: {=+TRANSPOSE(O5:O13)} -> 64.003401 | F16: 52.582736 | G16: 44.934338 | H16: 78.39608 | I16: 47.802488 | J16: 52.582736 | K16: 75.52793 | L16: 62.143234 | M16: 57.362985
E17: =+E15-E16 -> 0 | F17: =+F15-F16 -> 0 | G17: =+G15-G16 -> 0 | H17: =+H15-H16 -> 0 | I17: =+I15-I16 -> 0 | J17: =+J15-J16 -> 0 | K17: =+K15-K16 -> 0 | L17: =+L15-L16 -> 0 | M17: =+M15-M16 -> 0
E19: A | F19: A | G19: A | H19: B | I19: B | J19: B | K19: C | L19: C | M19: C
D20: A | E20: Agr | F20: Ind | G20: Serv | H20: Agr | I20: Ind | J20: Serv | K20: Agr | L20: Ind | M20: Serv
C21: A | D21: Agr | E21: {=+'IO_sub_model (2)'!E200:M208} -> 0.11867501 | F21: 0.076647393 | G21: 0.17473017 | H21: 0.012209906 | I21: 0.0048643383 | J21: 0.11931923 | K21: 0.033248744 | L21: 0.090236411 | M21: 0.030333533
C22: A | D22: Ind | E22: 0.11001872 | F22: 0.070894581 | G22: 0.1791501 | H22: 0.061562837 | I22: 0.040170067 | J22: 0.17036505 | K22: 0.027776973 | L22: 0.078388299 | M22: 0.1134284
C23: A | D23: Serv | E23: 0.015062598 | F23: 0.010544667 | G23: 0.01410229 | H23: 0.086008083 | I23: 0.085099484 | J23: 0.0668185 | K23: 0.081932989 | L23: 0.061637251 | M23: 0.11340183
C24: B | D24: =+D21 -> Agr | E24: 0.13262911 | F24: 0.10944989 | G24: 0.11553194 | H24: 0.08904386 | I24: 0.19984267 | J24: 0.16164641 | K24: 0.1264827 | L24: 0.14937683 | M24: 0.15158813
C25: B | D25: =+D22 -> Ind | E25: 0.059337507 | F25: 0.040919292 | G25: 0.068581333 | H25: 0.077377634 | I25: 0.1426941 | J25: 0.077401669 | K25: 0.11777117 | L25: 0.035562595 | M25: 0.13783589
C26: B | D26: =+D23 -> Serv | E26: 0.08718049 | F26: 0.083409005 | G26: 0.082572119 | H26: 0.028977781 | I26: 0.16585281 | J26: 0.038476168 | K26: 0.022292056 | L26: 0.086855229 | M26: 0.035209356
C27: C | D27: =+D24 -> Agr | E27: 0.058555034 | F27: 0.17753908 | G27: 0.177823 | H27: 0.10606331 | I27: 0.19529299 | J27: 0.028125267 | K27: 0.093433112 | L27: 0.14500214 | M27: 0.134745
C28: C | D28: =+D25 -> Ind | E28: 0.023490672 | F28: 0.13680415 | G28: 0.020824856 | H28: 0.10477982 | I28: 0.0064680234 | J28: 0.019975769 | K28: 0.094112852 | L28: 0.14496492 | M28: 0.029227844
C29: C | D29: =+D26 -> Serv | E29: 0.13510694 | F29: 0.04039338 | G29: 0.082999461 | H29: 0.11672769 | I29: 0.023499544 | J29: 0.0098599486 | K29: 0.042755004 | L29: 0.013905056 | M29: 0.11528481
D30: VA | E30: =+E14/E$15 -> 0.25994392 | F30: =+F14/F$15 -> 0.25339856 | G30: =+G14/G$15 -> 0.083684732 | H30: =+H14/H$15 -> 0.31724908 | I30: =+I14/I$15 -> 0.13621598 | J30: =+J14/J$15 -> 0.30801199 | K30: =+K14/K$15 -> 0.3601944 | L30: =+L14/L$15 -> 0.19407127 | M30: =+M14/M$15 -> 0.13894521
D31: X | E31: =SUM(E21:E30) -> 1 | F31: =SUM(F21:F30) -> 1 | G31: =SUM(G21:G30) -> 1 | H31: =SUM(H21:H30) -> 1 | I31: =SUM(I21:I30) -> 1 | J31: =SUM(J21:J30) -> 1 | K31: =SUM(K21:K30) -> 1 | L31: =SUM(L21:L30) -> 1 | M31: =SUM(M21:M30) -> 1
E34: A | F34: A | G34: A | H34: B | I34: B | J34: B | K34: C | L34: C | M34: C
D35: L | E35: Agr | F35: Ind | G35: Serv | H35: Agr | I35: Ind | J35: Serv | K35: Agr | L35: Ind | M35: Serv
C36: A | D36: Agr | E36: {=+MINVERSE(_xlfn.MUNIT(COUNTA($D$36:$D$44))-E21:M29)} -> 1.3075851 | F36: 0.26505464 | G36: 0.40599485 | H36: 0.19175414 | I36: 0.21755449 | J36: 0.30183843 | K36: 0.19839099 | L36: 0.30247998 | M36: 0.24982502
C37: A | D37: Ind | E37: 0.37083129 | F37: 1.3172609 | G37: 0.48549028 | H37: 0.30378842 | I37: 0.33300617 | J37: 0.40989875 | K37: 0.24967163 | L37: 0.3525283 | M37: 0.41374641
C38: A | D38: Serv | E38: 0.20747425 | F38: 0.19978002 | G38: 1.2405109 | H38: 0.2709229 | I38: 0.31123729 | J38: 0.23432539 | K38: 0.2532477 | L38: 0.26224416 | M38: 0.34320409
C39: B | D39: =+D36 -> Agr | E39: 0.53714444 | F39: 0.5070238 | G39: 0.60361355 | H39: 1.4734462 | I39: 0.66524536 | J39: 0.53235993 | K39: 0.48466634 | L39: 0.57829959 | M39: 0.63100508
C40: B | D40: =+D37 -> Ind | E40: 0.32247029 | F40: 0.29326232 | G40: 0.38407034 | H40: 0.3279726 | I40: 1.451627 | J40: 0.31192774 | K40: 0.35069081 | L40: 0.30485431 | M40: 0.45613562
C41: B | D41: =+D38 -> Serv | E41: 0.28395488 | F41: 0.27471938 | G41: 0.32192317 | H41: 0.21796515 | I41: 0.39108477 | J41: 1.2293354 | K41: 0.20307767 | L41: 0.29647925 | M41: 0.27414553
C42: C | D42: =+D39 -> Agr | E42: 0.42729764 | F42: 0.53696365 | G42: 0.62208055 | H42: 0.46933395 | I42: 0.61811533 | J42: 0.37911182 | K42: 1.4301653 | L42: 0.53752133 | M42: 0.59061254
C43: C | D43: =+D40 -> Ind | E43: 0.23396388 | F43: 0.36059832 | G43: 0.28314129 | H43: 0.31057952 | I43: 0.24478637 | J43: 0.2244952 | K43: 0.28310654 | L43: 1.3875098 | M43: 0.27978918
C44: C | D44: =+D41 -> Serv | E44: 0.34300632 | F44: 0.22872555 | G44: 0.32848678 | H44: 0.30167688 | I44: 0.242032 | J44: 0.20086643 | K44: 0.21454275 | L44: 0.22237551 | M44: 1.3509109
C46: Demand shock | E46: d_shock | F46: 1-d_shock | G46: FD | H46: fd_max | J46: Supply shock | L46: p_shock | M46: 1-p_shock | N46: X | O46: x_max
...

Sheet IO_sub_model (4)
E3: A | F3: A | G3: A | H3: B | I3: B | J3: B | K3: C | L3: C | M3: C
D4: Z | E4: Agr | F4: Ind | G4: Serv | H4: Agr | I4: Ind | J4: Serv | K4: Agr | L4: Ind | M4: Serv | N4: FD | O4: X | P4: AX | Q4: X
C5: A | D5: Agr | E5: {=+'IO_sub_model (3)'!E150:M158} -> 7.6500076 | F5: 4.0043316 | G5: 7.6500076 | H5: 1.0598954 | I5: 0.39850621 | J5: 6.1080509 | K5: 2.5620014 | L5: 5.5462883 | M5: 1.820911 | N5: =+O5-SUM(E5:M5) -> 30.610989 | O5: {=+TRANSPOSE(_xlfn.ANCHORARRAY(E15))} -> 67.410989 | P5: {=+MMULT(E21:M29,O5:O13)} -> 36.8 | Q5: =+P5+N5 -> 67.410989 | R5: =+Q5=O5 -> TRUE
C6: A | D6: Ind | E6: 7.1700599 | F6: 3.7551622 | G6: 7.8422419 | H6: 4.8976765 | I6: 1.9725425 | J6: 8.7377939 | K6: 2.2906474 | L6: 4.8906249 | M6: 6.4432509 | N6: =+O6-SUM(E6:M6) -> 4.2197802 | O6: 52.21978 | P6: 48 | Q6: =+P6+N6 -> 52.21978 | R6: =+Q6=O6 -> TRUE
C7: A | D7: Serv | E7: 1.3976607 | F7: 0.62076412 | G7: 0.7094447 | H7: 6.6444061 | I7: 4.037508 | J7: 3.4167438 | K7: 6.023642 | L7: 3.7714662 | M7: 6.3783644 | N7: =+O7-SUM(E7:M7) -> 11.624176 | O7: 44.624176 | P7: 33 | Q7: =+P7+N7 -> 44.624176 | R7: =+Q7=O7 -> TRUE
C8: B | D8: =+D5 -> Agr | E8: 8.9172688 | F8: 5.8119918 | G8: 5.3114434 | H8: 6.923397 | I8: 9.4178172 | J8: 8.3657272 | K8: 9.4178172 | L8: 9.2481937 | M8: 8.5863438 | N8: =+O8-SUM(E8:M8) -> 5.8549451 | O8: 77.854945 | P8: 72 | Q8: =+P8+N8 -> 77.854945 | R8: =+Q8=O8 -> TRUE
C9: B | D9: =+D6 -> Ind | E9: 4.0599836 | F9: 2.2451689 | G9: 3.1126056 | H9: 6.0551126 | I9: 6.6163718 | J9: 4.0821013 | K9: 8.7254619 | L9: 2.3472281 | M9: 7.7559661 | N9: =+O9-SUM(E9:M9) -> 2.4725275 | O9: 47.472527 | P9: 45 | Q9: =+P9+N9 -> 47.472527 | R9: =+Q9=O9 -> TRUE
C10: B | D10: =+D7 -> Serv | E10: 5.8093579 | F10: 4.2642116 | G10: 3.6371017 | H10: 2.4141581 | I10: 7.7132029 | J10: 2.0066612 | K10: 1.7557719 | L10: 5.2675422 | M10: 2.1319926 | N10: =+O10-SUM(E10:M10) -> 17.21978 | O10: 52.21978 | P10: 35 | Q10: =+P10+N10 -> 52.21978 | R10: =+Q10=O10 -> TRUE
C11: C | D11: =+D8 -> Agr | E11: 4.3206357 | F11: 9.1726876 | G11: 7.9264611 | H11: 8.157367 | I11: 9.1726876 | J11: 1.6668813 | K11: 7.0091924 | L11: 8.9417817 | M11: 7.6323056 | N11: =+O11-SUM(E11:M11) -> 11.006593 | O11: 75.006593 | P11: 64 | Q11: =+P11+N11 -> 75.006593 | R11: =+Q11=O11 -> TRUE
C12: C | D12: =+D9 -> Ind | E12: 1.8009016 | F12: 6.9962305 | G12: 1.0419787 | H12: 8.0421857 | I12: 0.40870532 | J12: 1.176402 | K12: 6.9791299 | L12: 8.7579152 | M12: 1.7965511 | N12: =+O12-SUM(E12:M12) -> 24.714286 | O12: 61.714286 | P12: 37 | Q12: =+P12+N12 -> 61.714286 | R12: =+Q12=O12 -> TRUE
C13: C | D13: =+D10 -> Serv | E13: 8.7363715 | F13: 2.1195274 | G13: 3.6586 | H13: 8.953015 | I13: 1.257652 | J13: 0.58045476 | K13: 3.2276623 | L13: 0.9674246 | M13: 6.4992924 | N13: =+O13-SUM(E13:M13) -> 20.967033 | O13: 56.967033 | P13: 36 | Q13: =+P13+N13 -> 56.967033 | R13: =+Q13=O13 -> TRUE
D14: VA | E14: =+E15-SUM(E5:E13) -> 17.548742 | F14: =+F15-SUM(F5:F13) -> 13.229705 | G14: =+G15-SUM(G5:G13) -> 3.7342913 | H14: =+H15-SUM(H5:H13) -> 24.707732 | I14: =+I15-SUM(I5:I13) -> 6.4775341 | J14: =+J15-SUM(J5:J13) -> 16.078964 | K14: =+K15-SUM(K5:K13) -> 27.015267 | L14: =+L15-SUM(L5:L13) -> 11.975821 | M14: =+M15-SUM(M5:M13) -> 7.9220549 | N14: =+SUM(E5:M13) -> 406.8
D15: X | E15: {=+'IO_sub_model (3)'!E184:M184} -> 67.410989 | F15: 52.21978 | G15: 44.624176 | H15: 77.854945 | I15: 47.472527 | J15: 52.21978 | K15: 75.006593 | L15: 61.714286 | M15: 56.967033
E16: {=+TRANSPOSE(O5:O13)} -> 67.410989 | F16: 52.21978 | G16: 44.624176 | H16: 77.854945 | I16: 47.472527 | J16: 52.21978 | K16: 75.006593 | L16: 61.714286 | M16: 56.967033
E17: =+E15-E16 -> 0 | F17: =+F15-F16 -> 0 | G17: =+G15-G16 -> 0 | H17: =+H15-H16 -> 0 | I17: =+I15-I16 -> 0 | J17: =+J15-J16 -> 0 | K17: =+K15-K16 -> 0 | L17: =+L15-L16 -> 0 | M17: =+M15-M16 -> 0
E19: A | F19: A | G19: A | H19: B | I19: B | J19: B | K19: C | L19: C | M19: C
D20: A | E20: Agr | F20: Ind | G20: Serv | H20: Agr | I20: Ind | J20: Serv | K20: Agr | L20: Ind | M20: Serv
C21: A | D21: Agr | E21: {=+'IO_sub_model (3)'!E200:M208} -> 0.11348309 | F21: 0.076682276 | G21: 0.17143191 | H21: 0.013613719 | I21: 0.0083944594 | J21: 0.11696815 | K21: 0.034157016 | L21: 0.089870412 | M21: 0.031964295
C22: A | D22: Ind | E22: 0.10636337 | F22: 0.071910723 | G22: 0.17573976 | H22: 0.062907712 | I22: 0.041551242 | J22: 0.16732728 | K22: 0.03053928 | L22: 0.079246237 | M22: 0.11310491
C23: A | D23: Serv | E23: 0.020733425 | F23: 0.011887528 | G23: 0.015898214 | H23: 0.085343405 | I23: 0.085049357 | J23: 0.065430069 | K23: 0.080308167 | L23: 0.061111721 | M23: 0.11196589
C24: B | D24: =+D21 -> Agr | E24: 0.13228212 | F24: 0.11129866 | G24: 0.11902614 | H24: 0.088926875 | I24: 0.19838458 | J24: 0.16020227 | K24: 0.12555986 | L24: 0.14985499 | M24: 0.15072478
C25: B | D25: =+D22 -> Ind | E25: 0.060227326 | F25: 0.042994607 | G25: 0.069751553 | H25: 0.077774284 | I25: 0.13937265 | J25: 0.078171553 | K25: 0.11632927 | L25: 0.038033788 | M25: 0.13614833
C26: B | D26: =+D23 -> Serv | E26: 0.086178203 | F26: 0.081658934 | G26: 0.081505184 | H26: 0.031008411 | I26: 0.16247719 | J26: 0.038427224 | K26: 0.023408235 | L26: 0.085353692 | M26: 0.037425025
C27: C | D27: =+D24 -> Agr | E27: 0.064093938 | F27: 0.17565542 | G27: 0.17762706 | H27: 0.10477648 | I27: 0.19322097 | J27: 0.031920496 | K27: 0.093447683 | L27: 0.14488998 | M27: 0.13397759
C28: C | D28: =+D25 -> Ind | E28: 0.026715253 | F28: 0.13397664 | G28: 0.023350094 | H28: 0.10329704 | I28: 0.0086093019 | J28: 0.0225279 | K28: 0.093046885 | L28: 0.14191066 | M28: 0.03153668
C29: C | D29: =+D26 -> Serv | E29: 0.12959863 | F29: 0.040588592 | G29: 0.081986948 | H29: 0.1149961 | I29: 0.026492206 | J29: 0.011115611 | K29: 0.043031714 | L29: 0.015675862 | M29: 0.11408866
D30: VA | E30: =+E14/E$15 -> 0.26032464 | F30: =+F14/F$15 -> 0.25334661 | G30: =+G14/G$15 -> 0.083683142 | H30: =+H14/H$15 -> 0.31735597 | I30: =+I14/I$15 -> 0.13644806 | J30: =+J14/J$15 -> 0.30790945 | K30: =+K14/K$15 -> 0.3601719 | L30: =+L14/L$15 -> 0.19405265 | M30: =+M14/M$15 -> 0.13906385
D31: X | E31: =SUM(E21:E30) -> 1 | F31: =SUM(F21:F30) -> 1 | G31: =SUM(G21:G30) -> 1 | H31: =SUM(H21:H30) -> 1 | I31: =SUM(I21:I30) -> 1 | J31: =SUM(J21:J30) -> 1 | K31: =SUM(K21:K30) -> 1 | L31: =SUM(L21:L30) -> 1 | M31: =SUM(M21:M30) -> 1
E34: A | F34: A | G34: A | H34: B | I34: B | J34: B | K34: C | L34: C | M34: C
D35: L | E35: Agr | F35: Ind | G35: Serv | H35: Agr | I35: Ind | J35: Serv | K35: Agr | L35: Ind | M35: Serv
C36: A | D36: Agr | E36: {=+MINVERSE(_xlfn.MUNIT(COUNTA($D$36:$D$44))-E21:M29)} -> 1.3024986 | F36: 0.26476433 | G36: 0.4021806 | H36: 0.19341621 | I36: 0.2217646 | J36: 0.29872085 | K36: 0.19945443 | L36: 0.30111385 | M36: 0.25211754
